Workbook

Sheet Resumo
A1: SIGA UEA · Relatório de execução de testes
A2: Histórias das sprints S02 e S03 (RBN01.01 a RBN01.10, RBN03.01 a RBN03.04 e RBN06.01) · casos de teste da matriz docs/matriz-ct-testes.md
A4: Data da execução | B4: 20/10/2026 21:01 (America/Manaus)
A5: Versão testada (commit) | B5: 449f0e6 · branch dev · repositório SIGA-UEA/sigauea
A6: Ambientes | B6: API Python 3.12 + FastAPI 0.143 com SQLite e com PostgreSQL 16; site Next.js 16 (build de produção) no Google Chrome; e-mail desligado (SMTP vazio) para não enviar mensagens reais
A7: Ferramentas | B7: pytest (API), Playwright com Chrome (navegador), script de carga em Python (httpx)
A8: Responsável pela execução | B8: Igor Leite de Almeida
A10: Casos de teste (CT) da matriz
A11: Aprovado | B11: =COUNTIF('Execucao por CT'!$L$2:$L$103,"Aprovado") | C11: =IF($B$15=0,0,B11/$B$15)
A12: Pendente | B12: =COUNTIF('Execucao por CT'!$L$2:$L$103,"Pendente") | C12: =IF($B$15=0,0,B12/$B$15)
A13: Não executado | B13: =COUNTIF('Execucao por CT'!$L$2:$L$103,"Não executado") | C13: =IF($B$15=0,0,B13/$B$15)
A14: Reprovado | B14: =COUNTIF('Execucao por CT'!$L$2:$L$103,"Reprovado") | C14: =IF($B$15=0,0,B14/$B$15)
A15: Total de CTs | B15: =SUM(B11:B14)
A17: Execuções
A18: Testes da API no SQLite: aprovados | B18: =COUNTIF('Testes automatizados'!$E$2:$E$114,"Aprovado")
A19: Testes da API no SQLite: pulados (funcionalidade futura) | B19: =COUNTIF('Testes automatizados'!$E$2:$E$114,"Pulado")
A20: Testes da API no SQLite: reprovados | B20: =COUNTIF('Testes automatizados'!$E$2:$E$114,"Reprovado")
A21: Testes da API no PostgreSQL 16: aprovados | B21: =COUNTIF('Testes automatizados'!$G$2:$G$114,"Aprovado")
A22: Testes da API no PostgreSQL 16: pulados | B22: =COUNTIF('Testes automatizados'!$G$2:$G$114,"Pulado")
A23: Testes da API no PostgreSQL 16: reprovados | B23: =COUNTIF('Testes automatizados'!$G$2:$G$114,"Reprovado")
A24: Checagens no navegador: aprovadas | B24: =COUNTIF('Testes no navegador'!$E$2:$E$60,"Aprovado")
A25: Checagens no navegador: reprovadas | B25: =COUNTIF('Testes no navegador'!$E$2:$E$60,"Reprovado")
A26: Carga RNF01: p95 em segundos (meta 3 s) | B26: ='Desempenho RNF01'!B6
A27: Carga RNF01: resultado | B27: ='Desempenho RNF01'!B11
A29: Funções de teste da API: 113 (122 execuções contando os parâmetros). Um teste pulado é um caso Pendente na matriz: a funcionalidade ainda não existe (CT-01.10-06 depende do módulo de ideias; CT-06.01-04, da troca de orientador pela coordenação).
A30: Os CTs com tempo simulado (expiração de link, bloqueio de 15 min, sessão de 60 min) adiantam o relógio no banco em vez de esperar; ficam como Aprovado com essa observação.
A31: Os totais desta aba são fórmulas sobre as outras abas e se atualizam ao abrir o arquivo; verde = valor vindo de outra aba.
A33: Por requisito
A34: Requisito | B34: CTs | C34: Aprovados | D34: Pendentes | E34: Não executados | F34: Reprovados
A35: RBN01.01 | B35: =COUNTIF('Execucao por CT'!$A$2:$A$103,A35) | C35: =COUNTIFS('Execucao por CT'!$A$2:$A$103,$A35,'Execucao por CT'!$L$2:$L$103,"Aprovado") | D35: =COUNTIFS('Execucao por CT'!$A$2:$A$103,$A35,'Execucao por CT'!$L$2:$L$103,"Pendente") | E35: =COUNTIFS('Execucao por CT'!$A$2:$A$103,$A35,'Execucao por CT'!$L$2:$L$103,"Não executado") | F35: =COUNTIFS('Execucao por CT'!$A$2:$A$103,$A35,'Execucao por CT'!$L$2:$L$103,"Reprovado")
A36: RBN01.02 | B36: =COUNTIF('Execucao por CT'!$A$2:$A$103,A36) | C36: =COUNTIFS('Execucao por CT'!$A$2:$A$103,$A36,'Execucao por CT'!$L$2:$L$103,"Aprovado") | D36: =COUNTIFS('Execucao por CT'!$A$2:$A$103,$A36,'Execucao por CT'!$L$2:$L$103,"Pendente") | E36: =COUNTIFS('Execucao por CT'!$A$2:$A$103,$A36,'Execucao por CT'!$L$2:$L$103,"Não executado") | F36: =COUNTIFS('Execucao por CT'!$A$2:$A$103,$A36,'Execucao por CT'!$L$2:$L$103,"Reprovado")
A37: RBN01.03 | B37: =COUNTIF('Execucao por CT'!$A$2:$A$103,A37) | C37: =COUNTIFS('Execucao por CT'!$A$2:$A$103,$A37,'Execucao por CT'!$L$2:$L$103,"Aprovado") | D37: =COUNTIFS('Execucao por CT'!$A$2:$A$103,$A37,'Execucao por CT'!$L$2:$L$103,"Pendente") | E37: =COUNTIFS('Execucao por CT'!$A$2:$A$103,$A37,'Execucao por CT'!$L$2:$L$103,"Não executado") | F37: =COUNTIFS('Execucao por CT'!$A$2:$A$103,$A37,'Execucao por CT'!$L$2:$L$103,"Reprovado")
A38: RBN01.04 | B38: =COUNTIF('Execucao por CT'!$A$2:$A$103,A38) | C38: =COUNTIFS('Execucao por CT'!$A$2:$A$103,$A38,'Execucao por CT'!$L$2:$L$103,"Aprovado") | D38: =COUNTIFS('Execucao por CT'!$A$2:$A$103,$A38,'Execucao por CT'!$L$2:$L$103,"Pendente") | E38: =COUNTIFS('Execucao por CT'!$A$2:$A$103,$A38,'Execucao por CT'!$L$2:$L$103,"Não executado") | F38: =COUNTIFS('Execucao por CT'!$A$2:$A$103,$A38,'Execucao por CT'!$L$2:$L$103,"Reprovado")
A39: RBN01.05 | B39: =COUNTIF('Execucao por CT'!$A$2:$A$103,A39) | C39: =COUNTIFS('Execucao por CT'!$A$2:$A$103,$A39,'Execucao por CT'!$L$2:$L$103,"Aprovado") | D39: =COUNTIFS('Execucao por CT'!$A$2:$A$103,$A39,'Execucao por CT'!$L$2:$L$103,"Pendente") | E39: =COUNTIFS('Execucao por CT'!$A$2:$A$103,$A39,'Execucao por CT'!$L$2:$L$103,"Não executado") | F39: =COUNTIFS('Execucao por CT'!$A$2:$A$103,$A39,'Execucao por CT'!$L$2:$L$103,"Reprovado")
A40: RBN01.06 | B40: =COUNTIF('Execucao por CT'!$A$2:$A$103,A40) | C40: =COUNTIFS('Execucao por CT'!$A$2:$A$103,$A40,'Execucao por CT'!$L$2:$L$103,"Aprovado") | D40: =COUNTIFS('Execucao por CT'!$A$2:$A$103,$A40,'Execucao por CT'!$L$2:$L$103,"Pendente") | E40: =COUNTIFS('Execucao por CT'!$A$2:$A$103,$A40,'Execucao por CT'!$L$2:$L$103,"Não executado") | F40: =COUNTIFS('Execucao por CT'!$A$2:$A$103,$A40,'Execucao por CT'!$L$2:$L$103,"Reprovado")
A41: RBN01.07 | B41: =COUNTIF('Execucao por CT'!$A$2:$A$103,A41) | C41: =COUNTIFS('Execucao por CT'!$A$2:$A$103,$A41,'Execucao por CT'!$L$2:$L$103,"Aprovado") | D41: =COUNTIFS('Execucao por CT'!$A$2:$A$103,$A41,'Execucao por CT'!$L$2:$L$103,"Pendente") | E41: =COUNTIFS('Execucao por CT'!$A$2:$A$103,$A41,'Execucao por CT'!$L$2:$L$103,"Não executado") | F41: =COUNTIFS('Execucao por CT'!$A$2:$A$103,$A41,'Execucao por CT'!$L$2:$L$103,"Reprovado")
A42: RBN01.08 | B42: =COUNTIF('Execucao por CT'!$A$2:$A$103,A42) | C42: =COUNTIFS('Execucao por CT'!$A$2:$A$103,$A42,'Execucao por CT'!$L$2:$L$103,"Aprovado") | D42: =COUNTIFS('Execucao por CT'!$A$2:$A$103,$A42,'Execucao por CT'!$L$2:$L$103,"Pendente") | E42: =COUNTIFS('Execucao por CT'!$A$2:$A$103,$A42,'Execucao por CT'!$L$2:$L$103,"Não executado") | F42: =COUNTIFS('Execucao por CT'!$A$2:$A$103,$A42,'Execucao por CT'!$L$2:$L$103,"Reprovado")
A43: RBN01.09 | B43: =COUNTIF('Execucao por CT'!$A$2:$A$103,A43) | C43: =COUNTIFS('Execucao por CT'!$A$2:$A$103,$A43,'Execucao por CT'!$L$2:$L$103,"Aprovado") | D43: =COUNTIFS('Execucao por CT'!$A$2:$A$103,$A43,'Execucao por CT'!$L$2:$L$103,"Pendente") | E43: =COUNTIFS('Execucao por CT'!$A$2:$A$103,$A43,'Execucao por CT'!$L$2:$L$103,"Não executado") | F43: =COUNTIFS('Execucao por CT'!$A$2:$A$103,$A43,'Execucao por CT'!$L$2:$L$103,"Reprovado")
A44: RBN01.10 | B44: =COUNTIF('Execucao por CT'!$A$2:$A$103,A44) | C44: =COUNTIFS('Execucao por CT'!$A$2:$A$103,$A44,'Execucao por CT'!$L$2:$L$103,"Aprovado") | D44: =COUNTIFS('Execucao por CT'!$A$2:$A$103,$A44,'Execucao por CT'!$L$2:$L$103,"Pendente") | E44: =COUNTIFS('Execucao por CT'!$A$2:$A$103,$A44,'Execucao por CT'!$L$2:$L$103,"Não executado") | F44: =COUNTIFS('Execucao por CT'!$A$2:$A$103,$A44,'Execucao por CT'!$L$2:$L$103,"Reprovado")
A45: RBN03.01 | B45: =COUNTIF('Execucao por CT'!$A$2:$A$103,A45) | C45: =COUNTIFS('Execucao por CT'!$A$2:$A$103,$A45,'Execucao por CT'!$L$2:$L$103,"Aprovado") | D45: =COUNTIFS('Execucao por CT'!$A$2:$A$103,$A45,'Execucao por CT'!$L$2:$L$103,"Pendente") | E45: =COUNTIFS('Execucao por CT'!$A$2:$A$103,$A45,'Execucao por CT'!$L$2:$L$103,"Não executado") | F45: =COUNTIFS('Execucao por CT'!$A$2:$A$103,$A45,'Execucao por CT'!$L$2:$L$103,"Reprovado")
...

Sheet Execucao por CT
A1: Requisito | B1: CT | C1: Tipo | D1: Passos | E1: Situação na matriz | F1: Como foi executado | G1: Teste(s) automatizado(s) | H1: API · SQLite | I1: API · PostgreSQL 16 | J1: Navegador | K1: Carga | L1: Resultado final | M1: Evidência | N1: Checagens no navegador | O1: Observação
A2: RBN01.01 | B2: CT-01.01-01 | C2: Funcional | D2: Cadastrar "Maria Silva", e-mail institucional, cargo Orientador, curso EC | E2: Parcial | F2: API (pytest) | G2: test_usuarios.py::test_ct_01_01_01_docente_nasce_inativo_e_sem_senha | H2: Aprovado | I2: Aprovado | J2: — | K2: — | L2: Aprovado | M2: junit-sqlite.xml; junit-postgresql.xml | N2: — | O2: Cria e confere o estado; o e-mail é conferido em CT-01.05-01.
A3: RBN01.01 | B3: CT-01.01-02 | C3: Negativo | D3: Enviar sem e-mail | E3: Coberto | F3: API (pytest) | G3: test_usuarios.py::test_ct_01_01_02_campo_obrigatorio_vazio_responde_400 | H3: Aprovado | I3: Aprovado | J3: — | K3: — | L3: Aprovado | M3: junit-sqlite.xml; junit-postgresql.xml | N3: — | O3: —
A4: RBN01.01 | B4: CT-01.01-03 | C4: Negativo | D4: Cadastrar com o mesmo e-mail | E4: Coberto | F4: API (pytest) | G4: test_usuarios.py::test_ct_01_01_03_email_duplicado_ignora_maiusculas | H4: Aprovado | I4: Aprovado | J4: — | K4: — | L4: Aprovado | M4: junit-sqlite.xml; junit-postgresql.xml | N4: — | O4: —
A5: RBN01.01 | B5: CT-01.01-04 | C5: Funcional | D5: Atribuir também perfil coordenador | E5: Coberto | F5: API (pytest) | G5: test_cts_complementares.py::test_ct_01_01_04_docente_recebe_tambem_o_perfil_de_coordenador | H5: Aprovado | I5: Aprovado | J5: — | K5: — | L5: Aprovado | M5: junit-sqlite.xml; junit-postgresql.xml | N5: — | O5: —
A6: RBN01.01 | B6: CT-01.01-05 | C6: Funcional | D6: Cadastrar cargo Coordenador sem curso | E6: Coberto | F6: API (pytest) | G6: test_usuarios.py::test_ct_01_01_05_coordenador_nao_exige_curso | H6: Aprovado | I6: Aprovado | J6: — | K6: — | L6: Aprovado | M6: junit-sqlite.xml; junit-postgresql.xml | N6: — | O6: —
A7: RBN01.01 | B7: CT-01.01-06 | C7: Segurança | D7: POST de cadastro de docente | E7: Coberto | F7: API (pytest) | G7: test_usuarios.py::test_ct_01_01_06_quem_nao_e_coordenador_recebe_403 | H7: Aprovado | I7: Aprovado | J7: — | K7: — | L7: Aprovado | M7: junit-sqlite.xml; junit-postgresql.xml | N7: — | O7: —
A8: RBN01.01 | B8: CT-01.01-07 | C8: Auditoria | D8: Consultar log | E8: Coberto | F8: API (pytest) | G8: test_usuarios.py::test_ct_01_01_07_criacao_fica_no_log | H8: Aprovado | I8: Aprovado | J8: — | K8: — | L8: Aprovado | M8: junit-sqlite.xml; junit-postgresql.xml | N8: — | O8: —
A9: RBN01.01 | B9: CT-01.01-08 | C9: Não funcional | D9: Preencher formulário | E9: Manual | F9: Navegador | G9: — | H9: — | I9: — | J9: Aprovado | K9: — | L9: Aprovado | M9: e2e-complementares.log; telas/complementar-docente-360.png; telas/complementar-docente-768.png | N9: formulário de docente em 360 px sem rolagem horizontal (largura 360) | formulário de docente em 768 px sem rolagem horizontal (largura 768) | O9: Manual: abrir a tela em 360 px (e 768 px) e conferir que não há rolagem horizontal. Parte de tela executada no navegador nesta rodada.
A10: RBN01.02 | B10: CT-01.02-01 | C10: Funcional | D10: Adicionar "Computação Quântica" | E10: Parcial | F10: API (pytest) + Navegador | G10: test_perfil.py::test_ct_01_02_01_e_01_02_07_coordenador_cria_renomeia_e_exclui_area | H10: Aprovado | I10: Aprovado | J10: Aprovado | K10: — | L10: Aprovado | M10: junit-sqlite.xml; junit-postgresql.xml; e2e-complementares.log; telas/complementar-docente-768.png | N10: coordenação cria a área "Computação Quântica" pela tela | a área nova aparece e pode ser selecionada no cadastro de docente | O10: Via API; a seleção na tela é manual. Parte de tela executada no navegador nesta rodada.
A11: RBN01.02 | B11: CT-01.02-02 | C11: Negativo | D11: Adicionar "IA" novamente | E11: Coberto | F11: API (pytest) | G11: test_perfil.py::test_ct_01_02_02_nome_repetido_ignora_maiusculas | H11: Aprovado | I11: Aprovado | J11: — | K11: — | L11: Aprovado | M11: junit-sqlite.xml; junit-postgresql.xml | N11: — | O11: —
A12: RBN01.02 | B12: CT-01.02-03 | C12: Negativo | D12: Adicionar nome vazio | E12: Coberto | F12: API (pytest) | G12: test_cts_complementares.py::test_ct_01_02_03_area_com_nome_vazio_e_recusada | H12: Aprovado | I12: Aprovado | J12: — | K12: — | L12: Aprovado | M12: junit-sqlite.xml; junit-postgresql.xml | N12: — | O12: —
... A103: RBN06.01 | B103: CT-06.01-06 | C103: Auditoria | D103: Consultar log | E103: Coberto | F103: API (pytest) | G103: test_cts_complementares.py::test_ct_06_01_06_vinculo_de_orientacao_fica_no_log | H103: Aprovado | I103: Aprovado | J103: — | K103: — | L103: Aprovado | M103: junit-sqlite.xml; junit-postgresql.xml | N103: — | O103: —

Sheet Testes automatizados
A1: Arquivo | B1: Teste | C1: Execuções (parâmetros) | D1: CT(s) | E1: SQLite | F1: Tempo SQLite (s) | G1: PostgreSQL 16 | H1: Tempo PostgreSQL (s)
A2: test_acesso.py | B2: test_ct_01_04_01_e_01_04_06_senha_gravada_com_bcrypt_e_nunca_devolvida | C2: 1 | D2: CT-01.04-01, CT-01.04-06 | E2: Aprovado | F2: 1.128 | G2: Aprovado | H2: 0.966
A3: test_acesso.py | B3: test_ct_01_04_02_a_01_04_04_criterios_da_senha | C3: 7 | D3: CT-01.04-02, CT-01.04-03, CT-01.04-04 | E3: Aprovado | F3: 4.388 | G3: Aprovado | H3: 3.963
A4: test_acesso.py | B4: test_ct_01_04_05_ativacao_recusa_senha_fraca_e_lista_criterios | C4: 1 | D4: CT-01.04-05 | E4: Aprovado | F4: 0.889 | G4: Aprovado | H4: 0.849
A5: test_acesso.py | B5: test_ct_01_05_02_e_01_05_04_link_ativa_a_conta_e_vale_uma_vez | C5: 1 | D5: CT-01.05-02, CT-01.05-04 | E5: Aprovado | F5: 1.016 | G5: Aprovado | H5: 0.933
A6: test_acesso.py | B6: test_ct_01_05_03_link_expirado | C6: 1 | D6: CT-01.05-03 | E6: Aprovado | F6: 1.106 | G6: Aprovado | H6: 0.748
A7: test_acesso.py | B7: test_ct_01_05_05_conta_nao_ativada_recebe_a_mesma_mensagem | C7: 1 | D7: CT-01.05-05 | E7: Aprovado | F7: 0.944 | G7: Aprovado | H7: 0.871
A8: test_acesso.py | B8: test_ct_01_05_06_falha_de_email_nao_desfaz_cadastro_e_permite_reenvio | C8: 1 | D8: CT-01.05-06 | E8: Aprovado | F8: 0.946 | G8: Aprovado | H8: 0.829
A9: test_acesso.py | B9: test_ct_01_06_01_login_devolve_usuario_e_cookie_httponly | C9: 1 | D9: CT-01.06-01 | E9: Aprovado | F9: 0.71 | G9: Aprovado | H9: 0.709
A10: test_acesso.py | B10: test_ct_01_06_02_e_01_06_03_mesma_mensagem_para_email_ou_senha_errados | C10: 1 | D10: CT-01.06-02, CT-01.06-03 | E10: Aprovado | F10: 0.781 | G10: Aprovado | H10: 0.794
A11: test_acesso.py | B11: test_ct_01_06_04_e_01_06_05_bloqueio_apos_3_falhas_mesmo_com_senha_correta | C11: 1 | D11: CT-01.06-04, CT-01.06-05 | E11: Aprovado | F11: 0.986 | G11: Aprovado | H11: 1.033
A12: test_acesso.py | B12: test_ct_01_06_07_sessao_expira_por_inatividade_e_renova_com_uso | C12: 1 | D12: CT-01.06-07 | E12: Aprovado | F12: 0.764 | G12: Aprovado | H12: 0.736
A13: test_acesso.py | B13: test_ct_01_07_01_e_01_07_02_resposta_igual_e_email_so_para_cadastrado | C13: 1 | D13: CT-01.07-01, CT-01.07-02 | E13: Aprovado | F13: 0.688 | G13: Aprovado | H13: 0.618
... A114: test_usuarios.py | B114: test_hu0108_coordenador_nao_inativa_a_si_mesmo | C114: 1 | D114: complementar (sem CT na matriz) | E114: Aprovado | F114: 0.815 | G114: Aprovado | H114: 1.54

Sheet Testes no navegador
A1: Roteiro | B1: Arquivo | C1: Checagem | D1: CT(s) | E1: Resultado | F1: Evidência
A2: Cadastro de TCC de ponta a ponta (aluno → orientador → aluno) | B2: docs/testes/e2e/cadastro_tcc.mjs | C2: aluno matriculado vê o convite para cadastrar (RBN08.01) | D2: — | E2: Aprovado | F2: e2e-cadastro_tcc.log
A3: Cadastro de TCC de ponta a ponta (aluno → orientador → aluno) | B3: docs/testes/e2e/cadastro_tcc.mjs | C3: passo 1 valida campos obrigatórios | D3: — | E3: Aprovado | F3: e2e-cadastro_tcc.log
A4: Cadastro de TCC de ponta a ponta (aluno → orientador → aluno) | B4: docs/testes/e2e/cadastro_tcc.mjs | C4: palavras-chave incluídas como chips | D4: — | E4: Aprovado | F4: e2e-cadastro_tcc.log
A5: Cadastro de TCC de ponta a ponta (aluno → orientador → aluno) | B5: docs/testes/e2e/cadastro_tcc.mjs | C5: erro some ao corrigir o campo | D5: — | E5: Aprovado | F5: e2e-cadastro_tcc.log
A6: Cadastro de TCC de ponta a ponta (aluno → orientador → aluno) | B6: docs/testes/e2e/cadastro_tcc.mjs | C6: rascunho salvo ao continuar (DS-FL01-B) | D6: CT-03.01-04 | E6: Aprovado | F6: e2e-cadastro_tcc.log
A7: Cadastro de TCC de ponta a ponta (aluno → orientador → aluno) | B7: docs/testes/e2e/cadastro_tcc.mjs | C7: pendência: orientador ainda não aceitou (RBN03.03) | D7: — | E7: Aprovado | F7: e2e-cadastro_tcc.log
A8: Cadastro de TCC de ponta a ponta (aluno → orientador → aluno) | B8: docs/testes/e2e/cadastro_tcc.mjs | C8: envio bloqueado enquanto há pendências | D8: CT-06.01-03 | E8: Aprovado | F8: e2e-cadastro_tcc.log
A9: Cadastro de TCC de ponta a ponta (aluno → orientador → aluno) | B9: docs/testes/e2e/cadastro_tcc.mjs | C9: orientador vê o pedido pendente (DS-FL03) | D9: — | E9: Aprovado | F9: e2e-cadastro_tcc.log
A10: Cadastro de TCC de ponta a ponta (aluno → orientador → aluno) | B10: docs/testes/e2e/cadastro_tcc.mjs | C10: orientador aceitou a orientação | D10: CT-06.01-01 | E10: Aprovado | F10: e2e-cadastro_tcc.log
A11: Cadastro de TCC de ponta a ponta (aluno → orientador → aluno) | B11: docs/testes/e2e/cadastro_tcc.mjs | C11: aluno vê o vínculo aceito | D11: — | E11: Aprovado | F11: e2e-cadastro_tcc.log
A12: Cadastro de TCC de ponta a ponta (aluno → orientador → aluno) | B12: docs/testes/e2e/cadastro_tcc.mjs | C12: protocolo único gerado: TCC-2026-00001 (RBN03.04) | D12: CT-03.04-07, CT-03.03-08, CT-03.01-08, CT-03.04-01 | E12: Aprovado | F12: e2e-cadastro_tcc.log
... A60: Cadastro de aluna, ativação e Salvar rascunho | B60: docs/testes/e2e/salvar_rascunho.mjs | C60: sem erros de JavaScript | D60: — | E60: Aprovado | F60: e2e-salvar_rascunho.log

Sheet Desempenho RNF01
A1: Teste de carga do cadastro de TCC (RNF01, CT-03.03-07 e CT-03.04-05)
A3: Data da execução | B3: 20/10/2026 20:33 | C3: carga-rnf01.log
A4: Submissões simultâneas | B4: 30 | C4: backend/scripts/carga_rnf01.py
A5: Tempo médio (s) | B5: 0.561 | C5: medido do envio até o retorno do protocolo
A6: p95 (s) | B6: 0.733 | C6: percentil 95 dos 30 tempos
A7: Tempo máximo (s) | B7: 0.734
A8: Meta do RNF01: p95 até (s) | B8: 3 | C8: planilha de requisitos, RNF01
A9: Protocolos distintos | B9: 30 | C9: RNF06: nenhum protocolo repetido
A11: Resultado RNF01 (p95 abaixo da meta) | B11: =IF(B6<B8,"Aprovado","Reprovado")
A12: Resultado RNF06 (30 protocolos distintos) | B12: =IF(B9=B4,"Aprovado","Reprovado")
A14: Valores em azul: copiados da saída do teste (evidencias/carga-rnf01.log).

Sheet Evidencias
A1: Arquivo (no repositório) | B1: Conteúdo
A2: docs/testes/evidencias/carga-rnf01.log | B2: Saída do teste de carga com 30 submissões simultâneas
A3: docs/testes/evidencias/e2e-cadastro_tcc.log | B3: Saída do roteiro: Cadastro de TCC de ponta a ponta (aluno → orientador → aluno)
A4: docs/testes/evidencias/e2e-complementares.log | B4: Saída do roteiro: Casos de tela e responsividade (360 e 768 px)
A5: docs/testes/evidencias/e2e-minhas_turmas.log | B5: Saída do roteiro: Minhas turmas (professor, aluno e coordenação)
A6: docs/testes/evidencias/e2e-salvar_rascunho.log | B6: Saída do roteiro: Cadastro de aluna, ativação e Salvar rascunho
A7: docs/testes/evidencias/junit-postgresql.xml | B7: Saída do pytest (formato JUnit) da suíte da API no PostgreSQL 16
A8: docs/testes/evidencias/junit-sqlite.xml | B8: Saída do pytest (formato JUnit) da suíte da API no SQLite
A9: docs/testes/evidencias/telas/cadastro-1-trabalho.png | B9: Captura de tela do teste no navegador
A10: docs/testes/evidencias/telas/cadastro-3-revisar-pendente.png | B10: Captura de tela do teste no navegador
A11: docs/testes/evidencias/telas/cadastro-4-orientacoes.png | B11: Captura de tela do teste no navegador
A12: docs/testes/evidencias/telas/cadastro-5-protocolo.png | B12: Captura de tela do teste no navegador
... A29: docs/testes/evidencias/telas/turmas-4-celular-turma.png | B29: Captura de tela do teste no navegador
